<?xml version="1.0" encoding="UTF-8"?>
<testng-results skipped="2" failed="1" ignored="0" total="5" passed="2">
  <reporter-output>
  </reporter-output>
  <suite name="Suite" duration-ms="15896" started-at="2020-05-02T06:35:34Z" finished-at="2020-05-02T06:35:50Z">
    <groups>
      <group name="sanity,regression">
        <method signature="apiTestGetCall.verifyGetCallStatus()[pri:0, instance:com.qa.test.apiTestGetCall@3b2cf7ab]" name="verifyGetCallStatus" class="com.qa.test.apiTestGetCall"/>
      </group> <!-- sanity,regression -->
    </groups>
    <test name="Test" duration-ms="15896" started-at="2020-05-02T06:35:34Z" finished-at="2020-05-02T06:35:50Z">
      <class name="com.qa.test.apiTestGetCall">
        <test-method status="PASS" signature="setUp()[pri:0, instance:com.qa.test.apiTestGetCall@3b2cf7ab]" name="setUp" is-config="true" duration-ms="3542" started-at="2020-05-02T06:35:34Z" finished-at="2020-05-02T06:35:38Z">
          <reporter-output>
          </reporter-output>
        </test-method> <!-- setUp -->
        <test-method status="SKIP" signature="verifyGetCallBody()[pri:0, instance:com.qa.test.apiTestGetCall@3b2cf7ab]" name="verifyGetCallBody" duration-ms="1096" started-at="2020-05-02T06:35:38Z" finished-at="2020-05-02T06:35:39Z">
          <exception class="java.lang.AssertionError">
            <message>
              <![CDATA[Response is incorrect  expected [230 Degree] but found [180 Degree]]]>
            </message>
            <full-stacktrace>
              <![CDATA[java.lang.AssertionError: Response is incorrect  expected [230 Degree] but found [180 Degree]
at org.testng.Assert.fail(Assert.java:96)
at org.testng.Assert.failNotEquals(Assert.java:776)
at org.testng.Assert.assertEqualsImpl(Assert.java:137)
at org.testng.Assert.assertEquals(Assert.java:118)
at com.qa.test.apiTestGetCall.verifyGetCallBody(apiTestGetCall.java:51)
at sun.reflect.NativeMethodAccessorImpl.invoke0(Native Method)
at sun.reflect.NativeMethodAccessorImpl.invoke(NativeMethodAccessorImpl.java:62)
at sun.reflect.DelegatingMethodAccessorImpl.invoke(DelegatingMethodAccessorImpl.java:43)
at java.lang.reflect.Method.invoke(Method.java:498)
at org.testng.internal.MethodInvocationHelper.invokeMethod(MethodInvocationHelper.java:124)
at org.testng.internal.Invoker.invokeMethod(Invoker.java:583)
at org.testng.internal.Invoker.invokeTestMethod(Invoker.java:719)
at org.testng.internal.Invoker.invokeTestMethods(Invoker.java:989)
at org.testng.internal.TestMethodWorker.invokeTestMethods(TestMethodWorker.java:125)
at org.testng.internal.TestMethodWorker.run(TestMethodWorker.java:109)
at org.testng.TestRunner.privateRun(TestRunner.java:648)
at org.testng.TestRunner.run(TestRunner.java:505)
at org.testng.SuiteRunner.runTest(SuiteRunner.java:455)
at org.testng.SuiteRunner.runSequentially(SuiteRunner.java:450)
at org.testng.SuiteRunner.privateRun(SuiteRunner.java:415)
at org.testng.SuiteRunner.run(SuiteRunner.java:364)
at org.testng.SuiteRunnerWorker.runSuite(SuiteRunnerWorker.java:52)
at org.testng.SuiteRunnerWorker.run(SuiteRunnerWorker.java:84)
at org.testng.TestNG.runSuitesSequentially(TestNG.java:1208)
at org.testng.TestNG.runSuitesLocally(TestNG.java:1137)
at org.testng.TestNG.runSuites(TestNG.java:1049)
at org.testng.TestNG.run(TestNG.java:1017)
at org.testng.remote.AbstractRemoteTestNG.run(AbstractRemoteTestNG.java:115)
at org.testng.remote.RemoteTestNG.initAndRun(RemoteTestNG.java:251)
at org.testng.remote.RemoteTestNG.main(RemoteTestNG.java:77)
]]>
            </full-stacktrace>
          </exception> <!-- java.lang.AssertionError -->
          <reporter-output>
          </reporter-output>
        </test-method> <!-- verifyGetCallBody -->
        <test-method status="PASS" signature="setUp()[pri:0, instance:com.qa.test.apiTestGetCall@3b2cf7ab]" name="setUp" is-config="true" duration-ms="2177" started-at="2020-05-02T06:35:39Z" finished-at="2020-05-02T06:35:41Z">
          <reporter-output>
          </reporter-output>
        </test-method> <!-- setUp -->
        <test-method status="SKIP" signature="verifyGetCallBody()[pri:0, instance:com.qa.test.apiTestGetCall@3b2cf7ab]" name="verifyGetCallBody" duration-ms="97" started-at="2020-05-02T06:35:41Z" finished-at="2020-05-02T06:35:41Z">
          <exception class="java.lang.AssertionError">
            <message>
              <![CDATA[Response is incorrect  expected [230 Degree] but found [180 Degree]]]>
            </message>
            <full-stacktrace>
              <![CDATA[java.lang.AssertionError: Response is incorrect  expected [230 Degree] but found [180 Degree]
at org.testng.Assert.fail(Assert.java:96)
at org.testng.Assert.failNotEquals(Assert.java:776)
at org.testng.Assert.assertEqualsImpl(Assert.java:137)
at org.testng.Assert.assertEquals(Assert.java:118)
at com.qa.test.apiTestGetCall.verifyGetCallBody(apiTestGetCall.java:51)
at sun.reflect.NativeMethodAccessorImpl.invoke0(Native Method)
at sun.reflect.NativeMethodAccessorImpl.invoke(NativeMethodAccessorImpl.java:62)
at sun.reflect.DelegatingMethodAccessorImpl.invoke(DelegatingMethodAccessorImpl.java:43)
at java.lang.reflect.Method.invoke(Method.java:498)
at org.testng.internal.MethodInvocationHelper.invokeMethod(MethodInvocationHelper.java:124)
at org.testng.internal.Invoker.invokeMethod(Invoker.java:583)
at org.testng.internal.Invoker.retryFailed(Invoker.java:839)
at org.testng.internal.Invoker.invokeTestMethods(Invoker.java:1010)
at org.testng.internal.TestMethodWorker.invokeTestMethods(TestMethodWorker.java:125)
at org.testng.internal.TestMethodWorker.run(TestMethodWorker.java:109)
at org.testng.TestRunner.privateRun(TestRunner.java:648)
at org.testng.TestRunner.run(TestRunner.java:505)
at org.testng.SuiteRunner.runTest(SuiteRunner.java:455)
at org.testng.SuiteRunner.runSequentially(SuiteRunner.java:450)
at org.testng.SuiteRunner.privateRun(SuiteRunner.java:415)
at org.testng.SuiteRunner.run(SuiteRunner.java:364)
at org.testng.SuiteRunnerWorker.runSuite(SuiteRunnerWorker.java:52)
at org.testng.SuiteRunnerWorker.run(SuiteRunnerWorker.java:84)
at org.testng.TestNG.runSuitesSequentially(TestNG.java:1208)
at org.testng.TestNG.runSuitesLocally(TestNG.java:1137)
at org.testng.TestNG.runSuites(TestNG.java:1049)
at org.testng.TestNG.run(TestNG.java:1017)
at org.testng.remote.AbstractRemoteTestNG.run(AbstractRemoteTestNG.java:115)
at org.testng.remote.RemoteTestNG.initAndRun(RemoteTestNG.java:251)
at org.testng.remote.RemoteTestNG.main(RemoteTestNG.java:77)
]]>
            </full-stacktrace>
          </exception> <!-- java.lang.AssertionError -->
          <reporter-output>
          </reporter-output>
        </test-method> <!-- verifyGetCallBody -->
        <test-method status="PASS" signature="setUp()[pri:0, instance:com.qa.test.apiTestGetCall@3b2cf7ab]" name="setUp" is-config="true" duration-ms="3358" started-at="2020-05-02T06:35:41Z" finished-at="2020-05-02T06:35:44Z">
          <reporter-output>
          </reporter-output>
        </test-method> <!-- setUp -->
        <test-method status="FAIL" signature="verifyGetCallBody()[pri:0, instance:com.qa.test.apiTestGetCall@3b2cf7ab]" name="verifyGetCallBody" duration-ms="143" started-at="2020-05-02T06:35:44Z" finished-at="2020-05-02T06:35:45Z">
          <exception class="java.lang.AssertionError">
            <message>
              <![CDATA[Response is incorrect  expected [230 Degree] but found [180 Degree]]]>
            </message>
            <full-stacktrace>
              <![CDATA[java.lang.AssertionError: Response is incorrect  expected [230 Degree] but found [180 Degree]
at org.testng.Assert.fail(Assert.java:96)
at org.testng.Assert.failNotEquals(Assert.java:776)
at org.testng.Assert.assertEqualsImpl(Assert.java:137)
at org.testng.Assert.assertEquals(Assert.java:118)
at com.qa.test.apiTestGetCall.verifyGetCallBody(apiTestGetCall.java:51)
at sun.reflect.NativeMethodAccessorImpl.invoke0(Native Method)
at sun.reflect.NativeMethodAccessorImpl.invoke(NativeMethodAccessorImpl.java:62)
at sun.reflect.DelegatingMethodAccessorImpl.invoke(DelegatingMethodAccessorImpl.java:43)
at java.lang.reflect.Method.invoke(Method.java:498)
at org.testng.internal.MethodInvocationHelper.invokeMethod(MethodInvocationHelper.java:124)
at org.testng.internal.Invoker.invokeMethod(Invoker.java:583)
at org.testng.internal.Invoker.retryFailed(Invoker.java:839)
at org.testng.internal.Invoker.invokeTestMethods(Invoker.java:1010)
at org.testng.internal.TestMethodWorker.invokeTestMethods(TestMethodWorker.java:125)
at org.testng.internal.TestMethodWorker.run(TestMethodWorker.java:109)
at org.testng.TestRunner.privateRun(TestRunner.java:648)
at org.testng.TestRunner.run(TestRunner.java:505)
at org.testng.SuiteRunner.runTest(SuiteRunner.java:455)
at org.testng.SuiteRunner.runSequentially(SuiteRunner.java:450)
at org.testng.SuiteRunner.privateRun(SuiteRunner.java:415)
at org.testng.SuiteRunner.run(SuiteRunner.java:364)
at org.testng.SuiteRunnerWorker.runSuite(SuiteRunnerWorker.java:52)
at org.testng.SuiteRunnerWorker.run(SuiteRunnerWorker.java:84)
at org.testng.TestNG.runSuitesSequentially(TestNG.java:1208)
at org.testng.TestNG.runSuitesLocally(TestNG.java:1137)
at org.testng.TestNG.runSuites(TestNG.java:1049)
at org.testng.TestNG.run(TestNG.java:1017)
at org.testng.remote.AbstractRemoteTestNG.run(AbstractRemoteTestNG.java:115)
at org.testng.remote.RemoteTestNG.initAndRun(RemoteTestNG.java:251)
at org.testng.remote.RemoteTestNG.main(RemoteTestNG.java:77)
]]>
            </full-stacktrace>
          </exception> <!-- java.lang.AssertionError -->
          <reporter-output>
          </reporter-output>
        </test-method> <!-- verifyGetCallBody -->
        <test-method status="PASS" signature="setUp()[pri:0, instance:com.qa.test.apiTestGetCall@3b2cf7ab]" name="setUp" is-config="true" duration-ms="4047" started-at="2020-05-02T06:35:45Z" finished-at="2020-05-02T06:35:49Z">
          <reporter-output>
          </reporter-output>
        </test-method> <!-- setUp -->
        <test-method status="PASS" signature="verifyGetCallStatus()[pri:0, instance:com.qa.test.apiTestGetCall@3b2cf7ab]" name="verifyGetCallStatus" duration-ms="2" started-at="2020-05-02T06:35:49Z" finished-at="2020-05-02T06:35:49Z">
          <reporter-output>
          </reporter-output>
        </test-method> <!-- verifyGetCallStatus -->
        <test-method status="PASS" signature="setUp()[pri:0, instance:com.qa.test.apiTestGetCall@3b2cf7ab]" name="setUp" is-config="true" duration-ms="1202" started-at="2020-05-02T06:35:49Z" finished-at="2020-05-02T06:35:50Z">
          <reporter-output>
          </reporter-output>
        </test-method> <!-- setUp -->
        <test-method status="PASS" signature="verifyHeadersGetCall()[pri:0, instance:com.qa.test.apiTestGetCall@3b2cf7ab]" name="verifyHeadersGetCall" duration-ms="3" started-at="2020-05-02T06:35:50Z" finished-at="2020-05-02T06:35:50Z">
          <reporter-output>
          </reporter-output>
        </test-method> <!-- verifyHeadersGetCall -->
      </class> <!-- com.qa.test.apiTestGetCall -->
    </test> <!-- Test -->
  </suite> <!-- Suite -->
</testng-results>
