<?xml version="1.0" encoding="UTF-8"?>
<!-- Generated by org.testng.reporters.JUnitReportReporter -->
<testsuite skipped="2" hostname="LAPTOP-FK5U4VG9" name="com.qa.test.apiTestGetCall" tests="5" failures="1" timestamp="02 May 2020 06:35:51 GMT" time="15.667" errors="0">
  <testcase name="verifyGetCallBody" time="1.345" classname="com.qa.test.apiTestGetCall">
    <failure type="java.lang.AssertionError" message="Response is incorrect  expected [230 Degree] but found [180 Degree]">
      <![CDATA[java.lang.AssertionError: Response is incorrect  expected [230 Degree] but found [180 Degree]
at org.testng.Assert.fail(Assert.java:96)
at org.testng.Assert.failNotEquals(Assert.java:776)
at org.testng.Assert.assertEqualsImpl(Assert.java:137)
at org.testng.Assert.assertEquals(Assert.java:118)
at com.qa.test.apiTestGetCall.verifyGetCallBody(apiTestGetCall.java:51)
at sun.reflect.NativeMethodAccessorImpl.invoke0(Native Method)
at sun.reflect.NativeMethodAccessorImpl.invoke(NativeMethodAccessorImpl.java:62)
at sun.reflect.DelegatingMethodAccessorImpl.invoke(DelegatingMethodAccessorImpl.java:43)
at java.lang.reflect.Method.invoke(Method.java:498)
at org.testng.internal.MethodInvocationHelper.invokeMethod(MethodInvocationHelper.java:124)
at org.testng.internal.Invoker.invokeMethod(Invoker.java:583)
at org.testng.internal.Invoker.retryFailed(Invoker.java:839)
at org.testng.internal.Invoker.invokeTestMethods(Invoker.java:1010)
at org.testng.internal.TestMethodWorker.invokeTestMethods(TestMethodWorker.java:125)
at org.testng.internal.TestMethodWorker.run(TestMethodWorker.java:109)
at org.testng.TestRunner.privateRun(TestRunner.java:648)
at org.testng.TestRunner.run(TestRunner.java:505)
at org.testng.SuiteRunner.runTest(SuiteRunner.java:455)
at org.testng.SuiteRunner.runSequentially(SuiteRunner.java:450)
at org.testng.SuiteRunner.privateRun(SuiteRunner.java:415)
at org.testng.SuiteRunner.run(SuiteRunner.java:364)
at org.testng.SuiteRunnerWorker.runSuite(SuiteRunnerWorker.java:52)
at org.testng.SuiteRunnerWorker.run(SuiteRunnerWorker.java:84)
at org.testng.TestNG.runSuitesSequentially(TestNG.java:1208)
at org.testng.TestNG.runSuitesLocally(TestNG.java:1137)
at org.testng.TestNG.runSuites(TestNG.java:1049)
at org.testng.TestNG.run(TestNG.java:1017)
at org.testng.remote.AbstractRemoteTestNG.run(AbstractRemoteTestNG.java:115)
at org.testng.remote.RemoteTestNG.initAndRun(RemoteTestNG.java:251)
at org.testng.remote.RemoteTestNG.main(RemoteTestNG.java:77)
]]>
    </failure>
  </testcase> <!-- verifyGetCallBody -->
  <testcase name="verifyGetCallStatus" time="4.049" classname="com.qa.test.apiTestGetCall"/>
  <testcase name="verifyHeadersGetCall" time="2.180" classname="com.qa.test.apiTestGetCall"/>
  <testcase name="verifyGetCallBody" time="4.454" classname="com.qa.test.apiTestGetCall">
    <skipped/>
  </testcase> <!-- verifyGetCallBody -->
  <testcase name="verifyGetCallBody" time="3.639" classname="com.qa.test.apiTestGetCall">
    <skipped/>
  </testcase> <!-- verifyGetCallBody -->
</testsuite> <!-- com.qa.test.apiTestGetCall -->
